[2025-03-19T05:19:48.707+0000] {local_task_job_runner.py:120} INFO - ::group::Pre task execution logs
[2025-03-19T05:19:48.728+0000] {taskinstance.py:2076} INFO - Dependencies all met for dep_context=non-requeueable deps ti=<TaskInstance: github_etl.transform manual__2025-03-19T05:19:31.557438+00:00 [queued]>
[2025-03-19T05:19:48.735+0000] {taskinstance.py:2076} INFO - Dependencies all met for dep_context=requeueable deps ti=<TaskInstance: github_etl.transform manual__2025-03-19T05:19:31.557438+00:00 [queued]>
[2025-03-19T05:19:48.735+0000] {taskinstance.py:2306} INFO - Starting attempt 1 of 1
[2025-03-19T05:19:48.821+0000] {taskinstance.py:2330} INFO - Executing <Task(PythonOperator): transform> on 2025-03-19 05:19:31.557438+00:00
[2025-03-19T05:19:48.825+0000] {standard_task_runner.py:63} INFO - Started process 7107 to run task
[2025-03-19T05:19:48.827+0000] {standard_task_runner.py:90} INFO - Running: ['***', 'tasks', 'run', 'github_etl', 'transform', 'manual__2025-03-19T05:19:31.557438+00:00', '--job-id', '11', '--raw', '--subdir', 'DAGS_FOLDER/github_etl.py', '--cfg-path', '/tmp/tmpdwazmngl']
[2025-03-19T05:19:48.829+0000] {standard_task_runner.py:91} INFO - Job 11: Subtask transform
[2025-03-19T05:19:48.865+0000] {task_command.py:426} INFO - Running <TaskInstance: github_etl.transform manual__2025-03-19T05:19:31.557438+00:00 [running]> on host cc427449653e
[2025-03-19T05:19:49.015+0000] {taskinstance.py:2648} INFO - Exporting env vars: AIRFLOW_CTX_DAG_OWNER='***' AIRFLOW_CTX_DAG_ID='github_etl' AIRFLOW_CTX_TASK_ID='transform' AIRFLOW_CTX_EXECUTION_DATE='2025-03-19T05:19:31.557438+00:00' AIRFLOW_CTX_TRY_NUMBER='1' AIRFLOW_CTX_DAG_RUN_ID='manual__2025-03-19T05:19:31.557438+00:00'
[2025-03-19T05:19:49.016+0000] {taskinstance.py:430} INFO - ::endgroup::
[2025-03-19T05:19:51.754+0000] {taskinstance.py:441} INFO - ::group::Post task execution logs
[2025-03-19T05:19:51.755+0000] {taskinstance.py:2905} ERROR - Task failed with exception
Traceback (most recent call last):
  File "/home/airflow/.local/lib/python3.10/site-packages/airflow/models/taskinstance.py", line 465, in _execute_task
    result = _execute_callable(context=context, **execute_callable_kwargs)
  File "/home/airflow/.local/lib/python3.10/site-packages/airflow/models/taskinstance.py", line 432, in _execute_callable
    return execute_callable(context=context, **execute_callable_kwargs)
  File "/home/airflow/.local/lib/python3.10/site-packages/airflow/models/baseoperator.py", line 401, in wrapper
    return func(self, *args, **kwargs)
  File "/home/airflow/.local/lib/python3.10/site-packages/airflow/operators/python.py", line 235, in execute
    return_value = self.execute_callable()
  File "/home/airflow/.local/lib/python3.10/site-packages/airflow/operators/python.py", line 252, in execute_callable
    return self.python_callable(*self.op_args, **self.op_kwargs)
  File "/opt/airflow/dags/github_etl.py", line 421, in transform
    df = spark.read.csv(EXTRACT_FILE, schema=schemaType, header=True)
  File "/home/airflow/.local/lib/python3.10/site-packages/pyspark/sql/readwriter.py", line 740, in csv
    return self._df(self._jreader.csv(self._spark._sc._jvm.PythonUtils.toSeq(path)))
  File "/home/airflow/.local/lib/python3.10/site-packages/py4j/java_gateway.py", line 1322, in __call__
    return_value = get_return_value(
  File "/home/airflow/.local/lib/python3.10/site-packages/pyspark/errors/exceptions/captured.py", line 185, in deco
    raise converted from None
pyspark.errors.exceptions.captured.AnalysisException: [UNSUPPORTED_DATA_TYPE_FOR_DATASOURCE] The CSV datasource doesn't support the column `actor` of the type "STRUCT<id: INT, login: STRING, gravatar_id: STRING, url: STRING, avatar_url: STRING>".
[2025-03-19T05:19:51.766+0000] {taskinstance.py:1206} INFO - Marking task as FAILED. dag_id=github_etl, task_id=transform, run_id=manual__2025-03-19T05:19:31.557438+00:00, execution_date=20250319T051931, start_date=20250319T051948, end_date=20250319T051951
[2025-03-19T05:19:51.779+0000] {standard_task_runner.py:110} ERROR - Failed to execute job 11 for task transform ([UNSUPPORTED_DATA_TYPE_FOR_DATASOURCE] The CSV datasource doesn't support the column `actor` of the type "STRUCT<id: INT, login: STRING, gravatar_id: STRING, url: STRING, avatar_url: STRING>".; 7107)
[2025-03-19T05:19:51.794+0000] {local_task_job_runner.py:240} INFO - Task exited with return code 1
[2025-03-19T05:19:51.809+0000] {taskinstance.py:3503} INFO - 0 downstream tasks scheduled from follow-on schedule check
[2025-03-19T05:19:51.817+0000] {local_task_job_runner.py:222} INFO - ::endgroup::
