[2025-03-19T07:56:26.487+0000] {local_task_job_runner.py:120} INFO - ::group::Pre task execution logs
[2025-03-19T07:56:26.505+0000] {taskinstance.py:2076} INFO - Dependencies all met for dep_context=non-requeueable deps ti=<TaskInstance: github_etl.transform manual__2025-03-19T07:56:23.050842+00:00 [queued]>
[2025-03-19T07:56:26.511+0000] {taskinstance.py:2076} INFO - Dependencies all met for dep_context=requeueable deps ti=<TaskInstance: github_etl.transform manual__2025-03-19T07:56:23.050842+00:00 [queued]>
[2025-03-19T07:56:26.512+0000] {taskinstance.py:2306} INFO - Starting attempt 1 of 1
[2025-03-19T07:56:26.522+0000] {taskinstance.py:2330} INFO - Executing <Task(PythonOperator): transform> on 2025-03-19 07:56:23.050842+00:00
[2025-03-19T07:56:26.525+0000] {standard_task_runner.py:63} INFO - Started process 826 to run task
[2025-03-19T07:56:26.527+0000] {standard_task_runner.py:90} INFO - Running: ['***', 'tasks', 'run', 'github_etl', 'transform', 'manual__2025-03-19T07:56:23.050842+00:00', '--job-id', '28', '--raw', '--subdir', 'DAGS_FOLDER/github_etl.py', '--cfg-path', '/tmp/tmpr9kruwuf']
[2025-03-19T07:56:26.529+0000] {standard_task_runner.py:91} INFO - Job 28: Subtask transform
[2025-03-19T07:56:26.565+0000] {task_command.py:426} INFO - Running <TaskInstance: github_etl.transform manual__2025-03-19T07:56:23.050842+00:00 [running]> on host 09bb9170f096
[2025-03-19T07:56:26.718+0000] {taskinstance.py:2648} INFO - Exporting env vars: AIRFLOW_CTX_DAG_OWNER='***' AIRFLOW_CTX_DAG_ID='github_etl' AIRFLOW_CTX_TASK_ID='transform' AIRFLOW_CTX_EXECUTION_DATE='2025-03-19T07:56:23.050842+00:00' AIRFLOW_CTX_TRY_NUMBER='1' AIRFLOW_CTX_DAG_RUN_ID='manual__2025-03-19T07:56:23.050842+00:00'
[2025-03-19T07:56:26.719+0000] {taskinstance.py:430} INFO - ::endgroup::
[2025-03-19T07:56:26.837+0000] {taskinstance.py:441} INFO - ::group::Post task execution logs
[2025-03-19T07:56:26.845+0000] {taskinstance.py:2905} ERROR - Task failed with exception
Traceback (most recent call last):
  File "/home/airflow/.local/lib/python3.10/site-packages/airflow/models/taskinstance.py", line 465, in _execute_task
    result = _execute_callable(context=context, **execute_callable_kwargs)
  File "/home/airflow/.local/lib/python3.10/site-packages/airflow/models/taskinstance.py", line 432, in _execute_callable
    return execute_callable(context=context, **execute_callable_kwargs)
  File "/home/airflow/.local/lib/python3.10/site-packages/airflow/models/baseoperator.py", line 401, in wrapper
    return func(self, *args, **kwargs)
  File "/home/airflow/.local/lib/python3.10/site-packages/airflow/operators/python.py", line 235, in execute
    return_value = self.execute_callable()
  File "/home/airflow/.local/lib/python3.10/site-packages/airflow/operators/python.py", line 252, in execute_callable
    return self.python_callable(*self.op_args, **self.op_kwargs)
  File "/opt/airflow/dags/github_etl.py", line 28, in transform
    spark = SparkSession.builder.appName("GitHubTransform").getOrCreate()
  File "/home/airflow/.local/lib/python3.10/site-packages/pyspark/sql/session.py", line 497, in getOrCreate
    sc = SparkContext.getOrCreate(sparkConf)
  File "/home/airflow/.local/lib/python3.10/site-packages/pyspark/context.py", line 515, in getOrCreate
    SparkContext(conf=conf or SparkConf())
  File "/home/airflow/.local/lib/python3.10/site-packages/pyspark/context.py", line 201, in __init__
    SparkContext._ensure_initialized(self, gateway=gateway, conf=conf)
  File "/home/airflow/.local/lib/python3.10/site-packages/pyspark/context.py", line 436, in _ensure_initialized
    SparkContext._gateway = gateway or launch_gateway(conf)
  File "/home/airflow/.local/lib/python3.10/site-packages/pyspark/java_gateway.py", line 107, in launch_gateway
    raise PySparkRuntimeError(
pyspark.errors.exceptions.base.PySparkRuntimeError: [JAVA_GATEWAY_EXITED] Java gateway process exited before sending its port number.
[2025-03-19T07:56:26.858+0000] {taskinstance.py:1206} INFO - Marking task as FAILED. dag_id=github_etl, task_id=transform, run_id=manual__2025-03-19T07:56:23.050842+00:00, execution_date=20250319T075623, start_date=20250319T075626, end_date=20250319T075626
[2025-03-19T07:56:26.869+0000] {standard_task_runner.py:110} ERROR - Failed to execute job 28 for task transform ([JAVA_GATEWAY_EXITED] Java gateway process exited before sending its port number.; 826)
[2025-03-19T07:56:26.911+0000] {local_task_job_runner.py:240} INFO - Task exited with return code 1
[2025-03-19T07:56:26.927+0000] {taskinstance.py:3503} INFO - 0 downstream tasks scheduled from follow-on schedule check
[2025-03-19T07:56:26.934+0000] {local_task_job_runner.py:222} INFO - ::endgroup::
